Workbook

Sheet Start Here
A1: HBS Weekly Company Scoreboard
A2: Working v1 — built for the Monday operating meeting
A4: Purpose
A5: Are we on pace to hit this month's revenue, profit/cash, sales, and production goals — and where is the flow breaking down? This scoreboard follows HBS's economic flow (Demand -> Opportunity -> Production -> Closeout/Cash) with a dedicated Georgia section on the Tune-Up Factory tab and dedicated tabs for Direct Install and Recurring Revenue, so leaders report their numbers every week and problems surface before the last week of the month.
A9: Setup
A10: Weeks in this month: | B10: 4 | C10: Current week: | D10: Wk1 (9/7-9/13)
A12: Color Legend — colors appear automatically the moment a weekly score is typed in
A13: GREEN | B13: On pace — actual meets or beats the Weekly Target.
A14: YELLOW | B14: Close — within 15% of the Weekly Target. Early warning, not yet a crisis.
A15: RED | B15: Off pace — more than 15% below the Weekly Target. Owner explains why + corrective action in the Issues & Actions tab.
A17: How to read the cells
A18: Blue text / pale blue fill | B18: A cell you fill in — a goal, a weekly score, or an owner name.
A19: Black text, no fill | B19: A formula — don't type over these (Weekly Target, MTD, % to Goal, Status).
A20: Orange italic "TBD" | B20: An owner that still needs to be assigned or confirmed.
A22: Suggested Monday meeting flow
A23: 1. Company Results — revenue, sales, deposits/collections, overall pace
A24: 2. Tune-Up Factory — Demand / Opportunity / Production / Closeout by utility program
A25: 3. Georgia — is the Georgia team getting enough productive work?
A26: 4. Direct Install — sales through closeout
A27: 5. Recurring Revenue — service contracts, Zentility, renewals
A28: 6. Aging & Stalled Work — anything HBS is sitting on internally
A29: 7. Red KPIs / Issues & Actions — only items needing a decision or corrective action
A30: 8. Commitments — every action leaves with one owner + one due date
A32: Open items to finalize with your leadership team
A33: • Owners marked TBD below are best-guess defaults based on current roles — confirm or reassign at the meeting.
A34: • Individual Monthly Goals for each sales stream/program still need to be set (only the $1,668,200 September sales total is entered).
... A37: • Georgia should have one single accountable owner for the overall score, not just per-KPI reporters — assign that on the Georgia section of the Tune-Up Factory tab.

Sheet Company Results
A1: Company Results
A2: Top-level revenue, sales, and cash pace for the month
A4: Revenue by Stream
A5: Program / KPI | B5: Owner | C5: Monthly Goal | D5: Weekly Target | E5: Wk1 9/7 | F5: Wk2 9/14 | G5: Wk3 9/21 | H5: Wk4 9/28 | I5: MTD Actual | J5: % to Monthly Goal | K5: Latest | L5: Status
A6: Tune-Up | B6: Michael Costa (Director of Operations) | C6: 800000 | D6: =IF(C6="","",C6/'Start Here'!$B$10) -> 200000 | I6: =SUM(E6:H6) -> 0 | J6: =IF(OR(C6="",C6=0),"",I6/C6) -> 0 | K6: =IFERROR(LOOKUP(2,1/(E6:H6<>""),E6:H6),"") | L6: =IF(D6="","Set Goal",IF(K6="","No Data",IF(K6>=D6,"GREEN",IF(K6>=0.85*D6,"YELLOW","RED")))) -> No Data
A7: Commissioning | B7: Devon Goforth (Director of Accounting) | C7: 50000 | D7: =IF(C7="","",C7/'Start Here'!$B$10) -> 12500 | I7: =SUM(E7:H7) -> 0 | J7: =IF(OR(C7="",C7=0),"",I7/C7) -> 0 | K7: =IFERROR(LOOKUP(2,1/(E7:H7<>""),E7:H7),"") | L7: =IF(D7="","Set Goal",IF(K7="","No Data",IF(K7>=D7,"GREEN",IF(K7>=0.85*D7,"YELLOW","RED")))) -> No Data
A8: Consulting / Ongoing | B8: Devon Goforth (Director of Accounting) | C8: 45000 | D8: =IF(C8="","",C8/'Start Here'!$B$10) -> 11250 | I8: =SUM(E8:H8) -> 0 | J8: =IF(OR(C8="",C8=0),"",I8/C8) -> 0 | K8: =IFERROR(LOOKUP(2,1/(E8:H8<>""),E8:H8),"") | L8: =IF(D8="","Set Goal",IF(K8="","No Data",IF(K8>=D8,"GREEN",IF(K8>=0.85*D8,"YELLOW","RED")))) -> No Data
A9: BAS / Controls | B9: Devon Goforth (Director of Accounting) | C9: 105000 | D9: =IF(C9="","",C9/'Start Here'!$B$10) -> 26250 | E9: 720 | I9: =SUM(E9:H9) -> 720 | J9: =IF(OR(C9="",C9=0),"",I9/C9) -> 0.0068571429 | K9: =IFERROR(LOOKUP(2,1/(E9:H9<>""),E9:H9),"") -> 720 | L9: =IF(D9="","Set Goal",IF(K9="","No Data",IF(K9>=D9,"GREEN",IF(K9>=0.85*D9,"YELLOW","RED")))) -> RED
A10: Direct Install | B10: Devon Goforth (Director of Accounting) | C10: 600000 | D10: =IF(C10="","",C10/'Start Here'!$B$10) -> 150000 | I10: =SUM(E10:H10) -> 0 | J10: =IF(OR(C10="",C10=0),"",I10/C10) -> 0 | K10: =IFERROR(LOOKUP(2,1/(E10:H10<>""),E10:H10),"") | L10: =IF(D10="","Set Goal",IF(K10="","No Data",IF(K10>=D10,"GREEN",IF(K10>=0.85*D10,"YELLOW","RED")))) -> No Data
A11: TOTAL HBS REVENUE | B11: Mark Gill (Fractional COO) | C11: =SUM(C6:C10) -> 1600000 | D11: =IF(C11="","",C11/'Start Here'!$B$10) -> 400000 | E11: =SUM(E6:E10) -> 720 | F11: =SUM(F6:F10) -> 0 | G11: =SUM(G6:G10) -> 0 | H11: =SUM(H6:H10) -> 0 | I11: =SUM(I6:I10) -> 720 | J11: =IF(OR(C11="",C11=0),"",I11/C11) -> 0.00045 | K11: =IFERROR(LOOKUP(2,1/(E11:H11<>""),E11:H11),"") -> 0 | L11: =IF(D11="","Set Goal",IF(K11="","No Data",IF(K11>=D11,"GREEN",IF(K11>=0.85*D11,"YELLOW","RED")))) -> RED
A13: Sales / New Work by Program (September goal: $1,668,200 total)
A14: Program / KPI | B14: Owner | C14: Monthly Goal | D14: Weekly Target | E14: Wk1 9/7 | F14: Wk2 9/14 | G14: Wk3 9/21 | H14: Wk4 9/28 | I14: MTD Actual | J14: % to Monthly Goal | K14: Latest | L14: Status
A15: BGE BPTU Phase 1 | B15: Adriana | C15: 86700 | D15: =IF(C15="","",C15/'Start Here'!$B$10) -> 21675 | E15: 12750 | F15: 0 | I15: =SUM(E15:H15) -> 12750 | J15: =IF(OR(C15="",C15=0),"",I15/C15) -> 0.14705882 | K15: =IFERROR(LOOKUP(2,1/(E15:H15<>""),E15:H15),"") -> 0 | L15: =IF(D15="","Set Goal",IF(K15="","No Data",IF(K15>=D15,"GREEN",IF(K15>=0.85*D15,"YELLOW","RED")))) -> RED
A16: BGE BPTU Phase 2 | B16: Adriana | C16: 300000 | D16: =IF(C16="","",C16/'Start Here'!$B$10) -> 75000 | E16: 10798 | F16: 64334 | I16: =SUM(E16:H16) -> 75132 | J16: =IF(OR(C16="",C16=0),"",I16/C16) -> 0.25044 | K16: =IFERROR(LOOKUP(2,1/(E16:H16<>""),E16:H16),"") -> 64334 | L16: =IF(D16="","Set Goal",IF(K16="","No Data",IF(K16>=D16,"GREEN",IF(K16>=0.85*D16,"YELLOW","RED")))) -> YELLOW
A17: BGE Tune-Up | B17: Adriana | C17: 240000 | D17: =IF(C17="","",C17/'Start Here'!$B$10) -> 60000 | E17: 28901 | F17: 187145 | I17: =SUM(E17:H17) -> 216046 | J17: =IF(OR(C17="",C17=0),"",I17/C17) -> 0.90019167 | K17: =IFERROR(LOOKUP(2,1/(E17:H17<>""),E17:H17),"") -> 187145 | L17: =IF(D17="","Set Goal",IF(K17="","No Data",IF(K17>=D17,"GREEN",IF(K17>=0.85*D17,"YELLOW","RED")))) -> GREEN
A18: Pepco | B18: Adriana | C18: 240000 | D18: =IF(C18="","",C18/'Start Here'!$B$10) -> 60000 | E18: 0 | F18: 21547 | I18: =SUM(E18:H18) -> 21547 | J18: =IF(OR(C18="",C18=0),"",I18/C18) -> 0.089779167 | K18: =IFERROR(LOOKUP(2,1/(E18:H18<>""),E18:H18),"") -> 21547 | L18: =IF(D18="","Set Goal",IF(K18="","No Data",IF(K18>=D18,"GREEN",IF(K18>=0.85*D18,"YELLOW","RED")))) -> RED
A19: Delmarva | B19: Adriana | C19: 60000 | D19: =IF(C19="","",C19/'Start Here'!$B$10) -> 15000 | E19: 33940 | F19: 0 | I19: =SUM(E19:H19) -> 33940 | J19: =IF(OR(C19="",C19=0),"",I19/C19) -> 0.56566667 | K19: =IFERROR(LOOKUP(2,1/(E19:H19<>""),E19:H19),"") -> 0 | L19: =IF(D19="","Set Goal",IF(K19="","No Data",IF(K19>=D19,"GREEN",IF(K19>=0.85*D19,"YELLOW","RED")))) -> RED
A20: SMECO | B20: Adriana | C20: 5000 | D20: =IF(C20="","",C20/'Start Here'!$B$10) -> 1250 | E20: 0 | F20: 0 | I20: =SUM(E20:H20) -> 0 | J20: =IF(OR(C20="",C20=0),"",I20/C20) -> 0 | K20: =IFERROR(LOOKUP(2,1/(E20:H20<>""),E20:H20),"") -> 0 | L20: =IF(D20="","Set Goal",IF(K20="","No Data",IF(K20>=D20,"GREEN",IF(K20>=0.85*D20,"YELLOW","RED")))) -> RED
A21: WGL | B21: Adriana | C21: 2500 | D21: =IF(C21="","",C21/'Start Here'!$B$10) -> 625 | E21: 0 | F21: 0 | I21: =SUM(E21:H21) -> 0 | J21: =IF(OR(C21="",C21=0),"",I21/C21) -> 0 | K21: =IFERROR(LOOKUP(2,1/(E21:H21<>""),E21:H21),"") -> 0 | L21: =IF(D21="","Set Goal",IF(K21="","No Data",IF(K21>=D21,"GREEN",IF(K21>=0.85*D21,"YELLOW","RED")))) -> RED
A22: Georgia | B22: Adriana | C22: 49000 | D22: =IF(C22="","",C22/'Start Here'!$B$10) -> 12250 | E22: 0 | F22: 0 | I22: =SUM(E22:H22) -> 0 | J22: =IF(OR(C22="",C22=0),"",I22/C22) -> 0 | K22: =IFERROR(LOOKUP(2,1/(E22:H22<>""),E22:H22),"") -> 0 | L22: =IF(D22="","Set Goal",IF(K22="","No Data",IF(K22>=D22,"GREEN",IF(K22>=0.85*D22,"YELLOW","RED")))) -> RED
A23: Virginia / CGS | B23: Adriana | C23: 25000 | D23: =IF(C23="","",C23/'Start Here'!$B$10) -> 6250 | E23: 0 | F23: 0 | I23: =SUM(E23:H23) -> 0 | J23: =IF(OR(C23="",C23=0),"",I23/C23) -> 0 | K23: =IFERROR(LOOKUP(2,1/(E23:H23<>""),E23:H23),"") -> 0 | L23: =IF(D23="","Set Goal",IF(K23="","No Data",IF(K23>=D23,"GREEN",IF(K23>=0.85*D23,"YELLOW","RED")))) -> RED
A24: Direct Install | B24: Adriana | C24: 300000 | D24: =IF(C24="","",C24/'Start Here'!$B$10) -> 75000 | E24: 0 | F24: 0 | I24: =SUM(E24:H24) -> 0 | J24: =IF(OR(C24="",C24=0),"",I24/C24) -> 0 | K24: =IFERROR(LOOKUP(2,1/(E24:H24<>""),E24:H24),"") -> 0 | L24: =IF(D24="","Set Goal",IF(K24="","No Data",IF(K24>=D24,"GREEN",IF(K24>=0.85*D24,"YELLOW","RED")))) -> RED
A25: BAS | B25: Adriana | C25: 150000 | D25: =IF(C25="","",C25/'Start Here'!$B$10) -> 37500 | E25: 4500 | F25: 4800 | I25: =SUM(E25:H25) -> 9300 | J25: =IF(OR(C25="",C25=0),"",I25/C25) -> 0.062 | K25: =IFERROR(LOOKUP(2,1/(E25:H25<>""),E25:H25),"") -> 4800 | L25: =IF(D25="","Set Goal",IF(K25="","No Data",IF(K25>=D25,"GREEN",IF(K25>=0.85*D25,"YELLOW","RED")))) -> RED
A26: Commissioning | B26: Adriana | C26: 75000 | D26: =IF(C26="","",C26/'Start Here'!$B$10) -> 18750 | E26: 0 | F26: 0 | I26: =SUM(E26:H26) -> 0 | J26: =IF(OR(C26="",C26=0),"",I26/C26) -> 0 | K26: =IFERROR(LOOKUP(2,1/(E26:H26<>""),E26:H26),"") -> 0 | L26: =IF(D26="","Set Goal",IF(K26="","No Data",IF(K26>=D26,"GREEN",IF(K26>=0.85*D26,"YELLOW","RED")))) -> RED
... A31: Zentility | B31: Adriana | C31: 10000 | D31: =IF(C31="","",C31/'Start Here'!$B$10) -> 2500 | E31: 0 | F31: 0 | I31: =SUM(E31:H31) -> 0 | J31: =IF(OR(C31="",C31=0),"",I31/C31) -> 0 | K31: =IFERROR(LOOKUP(2,1/(E31:H31<>""),E31:H31),"") -> 0 | L31: =IF(D31="","Set Goal",IF(K31="","No Data",IF(K31>=D31,"GREEN",IF(K31>=0.85*D31,"YELLOW","RED")))) -> RED
A32: TOTAL SALES | B32: Adriana | C32: 1668200 | D32: =IF(C32="","",C32/'Start Here'!$B$10) -> 417050 | E32: =SUM(E15:E31) -> 95439 | F32: =SUM(F15:F31) -> 305416 | G32: =SUM(G15:G31) -> 0 | H32: =SUM(H15:H31) -> 0 | I32: =SUM(I15:I31) -> 400855 | J32: =IF(OR(C32="",C32=0),"",I32/C32) -> 0.24029193 | K32: =IFERROR(LOOKUP(2,1/(E32:H32<>""),E32:H32),"") -> 0 | L32: =IF(D32="","Set Goal",IF(K32="","No Data",IF(K32>=D32,"GREEN",IF(K32>=0.85*D32,"YELLOW","RED")))) -> RED
A33: Sum of streams entered above | C33: =SUM(C15:C31) -> 1663200
A34: Unallocated (Total goal minus streams entered) | C34: =C32-C33 -> 5000
A36: Cash / Collections (bank balance intentionally excluded)
A37: Program / KPI | B37: Owner | C37: Monthly Goal | D37: Weekly Target | E37: Wk1 9/7 | F37: Wk2 9/14 | G37: Wk3 9/21 | H37: Wk4 9/28 | I37: MTD Actual | J37: % to Monthly Goal | K37: Latest | L37: Status
A38: Deposits Received | B38: Devon Goforth (Director of Accounting) | C38: =C11 -> 1600000 | D38: =IF(C38="","",C38/'Start Here'!$B$10) -> 400000 | E38: 130507.37 | F38: 270601.2 | I38: =SUM(E38:H38) -> 401108.57 | J38: =IF(OR(C38="",C38=0),"",I38/C38) -> 0.25069286 | K38: =IFERROR(LOOKUP(2,1/(E38:H38<>""),E38:H38),"") -> 270601.2 | L38: =IF(D38="","Set Goal",IF(K38="","No Data",IF(K38>=D38,"GREEN",IF(K38>=0.85*D38,"YELLOW","RED")))) -> RED
A41: Tune-Up Factory Summary (auto-populated from the Tune-Up Factory tab)
A42: Program / KPI | B42: Owner | C42: Monthly Goal | D42: Weekly Target | E42: Wk1 9/7 | F42: Wk2 9/14 | G42: Wk3 9/21 | H42: Wk4 9/28 | I42: MTD Actual | J42: % to Monthly Goal | K42: Latest | L42: Status
A43: Pre-Approvals Submitted — Total $ This Week | B43: Michael Costa | D43: =IF(C43="","",C43/'Start Here'!$B$10) | E43: =SUM('Tune-Up Factory'!E8,'Tune-Up Factory'!E19,'Tune-Up Factory'!E33,'Tune-Up Factory'!E44,'Tune-Up Factory'!E55,'Tune-Up Factory'!E66,'Tune-Up Factory'!E80,'Tune-Up Factory'!E93) -> 41021 | F43: =SUM('Tune-Up Factory'!F8,'Tune-Up Factory'!F19,'Tune-Up Factory'!F33,'Tune-Up Factory'!F44,'Tune-Up Factory'!F55,'Tune-Up Factory'!F66,'Tune-Up Factory'!F80,'Tune-Up Factory'!F93) -> 7440 | G43: =SUM('Tune-Up Factory'!G8,'Tune-Up Factory'!G19,'Tune-Up Factory'!G33,'Tune-Up Factory'!G44,'Tune-Up Factory'!G55,'Tune-Up Factory'!G66,'Tune-Up Factory'!G80,'Tune-Up Factory'!G93) -> 0 | H43: =SUM('Tune-Up Factory'!H8,'Tune-Up Factory'!H19,'Tune-Up Factory'!H33,'Tune-Up Factory'!H44,'Tune-Up Factory'!H55,'Tune-Up Factory'!H66,'Tune-Up Factory'!H80,'Tune-Up Factory'!H93) -> 0 | I43: =SUM(E43:H43) -> 48461 | J43: =IF(OR(C43="",C43=0),"",I43/C43) | K43: =IFERROR(LOOKUP(2,1/(E43:H43<>""),E43:H43),"") -> 0 | L43: =IF(D43="","Set Goal",IF(K43="","No Data",IF(K43>=D43,"GREEN",IF(K43>=0.85*D43,"YELLOW","RED")))) -> Set Goal
A44: Implementations Scheduled — Est. Incentive $ This Week | B44: Michael Costa | D44: =IF(C44="","",C44/'Start Here'!$B$10) | E44: =SUM('Tune-Up Factory'!E10,'Tune-Up Factory'!E21,'Tune-Up Factory'!E35,'Tune-Up Factory'!#REF!,'Tune-Up Factory'!E57,'Tune-Up Factory'!E68,'Tune-Up Factory'!E82,'Tune-Up Factory'!E95) -> #REF! | F44: =SUM('Tune-Up Factory'!G10,'Tune-Up Factory'!F21,'Tune-Up Factory'!F35,'Tune-Up Factory'!F46,'Tune-Up Factory'!F57,'Tune-Up Factory'!F68,'Tune-Up Factory'!F82,'Tune-Up Factory'!F95) -> 207684 | G44: =SUM('Tune-Up Factory'!#REF!,'Tune-Up Factory'!G21,'Tune-Up Factory'!G35,'Tune-Up Factory'!G46,'Tune-Up Factory'!G57,'Tune-Up Factory'!G68,'Tune-Up Factory'!G82,'Tune-Up Factory'!G95) -> #REF! | H44: =SUM('Tune-Up Factory'!H10,'Tune-Up Factory'!H21,'Tune-Up Factory'!H35,'Tune-Up Factory'!H46,'Tune-Up Factory'!H57,'Tune-Up Factory'!H68,'Tune-Up Factory'!H82,'Tune-Up Factory'!H95) -> 0 | I44: =SUM(E44:H44) -> #REF! | J44: =IF(OR(C44="",C44=0),"",I44/C44) | K44: =IFERROR(LOOKUP(2,1/(E44:H44<>""),E44:H44),"") -> 0 | L44: =IF(D44="","Set Goal",IF(K44="","No Data",IF(K44>=D44,"GREEN",IF(K44>=0.85*D44,"YELLOW","RED")))) -> Set Goal

Sheet Tune-Up Factory
A1: Tune-Up Factory
A2: Demand -> Opportunity -> Production -> Closeout/Cash, by utility program
A4: PRIORITY PUSH: EmPower MD Prescriptive HVAC Tune-Ups
A5: Program / KPI | B5: Owner | C5: Monthly Goal | D5: Weekly Target | E5: Wk1 9/7 | F5: Wk2 9/14 | G5: Wk3 9/21 | H5: Wk4 9/28 | I5: MTD Actual | J5: % to Monthly Goal | K5: Latest | L5: Status
A6: Audits Completed | B6: Steve Weaver (PM) | D6: =IF(C6="","",C6/'Start Here'!$B$10) | F6: 0 | I6: =SUM(E6:H6) -> 0 | J6: =IF(OR(C6="",C6=0),"",I6/C6) | K6: =IFERROR(LOOKUP(2,1/(E6:H6<>""),E6:H6),"") -> 0 | L6: =IF(D6="","Set Goal",IF(K6="","No Data",IF(K6>=D6,"GREEN",IF(K6>=0.85*D6,"YELLOW","RED")))) -> Set Goal
A7: Pre-Approvals Submitted (count) | B7: Steve Weaver (PM) | F7: 7 | I7: =SUM(E7:H7) -> 7 | K7: {=IFERROR(LOOKUP(2,1/(E7:H7<>""),E7:H7),"")} -> 7 | L7: =IF(D7="","Set Goal",IF(K7="","No Data",IF(K7>=D7,"GREEN",IF(K7>=0.85*D7,"YELLOW","RED")))) -> Set Goal
A8: Pre-Approvals Submitted ($ Value) | B8: Steve Weaver (PM) | C8: 80000 | D8: =IF(C8="","",C8/'Start Here'!$B$10) -> 20000 | F8: 7440 | I8: =SUM(E8:H8) -> 7440 | J8: =IF(OR(C8="",C8=0),"",I8/C8) -> 0.093 | K8: =IFERROR(LOOKUP(2,1/(E8:H8<>""),E8:H8),"") -> 7440 | L8: =IF(D8="","Set Goal",IF(K8="","No Data",IF(K8>=D8,"GREEN",IF(K8>=0.85*D8,"YELLOW","RED")))) -> RED
A9: Pre-Approvals Approved (count) | B9: Steve Weaver (PM) | D9: =IF(C9="","",C9/'Start Here'!$B$10) | I9: =SUM(E9:H9) -> 0 | J9: =IF(OR(C9="",C9=0),"",I9/C9) | K9: =IFERROR(LOOKUP(2,1/(E9:H9<>""),E9:H9),"") | L9: =IF(D9="","Set Goal",IF(K9="","No Data",IF(K9>=D9,"GREEN",IF(K9>=0.85*D9,"YELLOW","RED")))) -> Set Goal
A10: Implementations Scheduled (Est. Incentive $) | B10: David Rodriguez (Ops Mgr) | C10: 80000 | D10: =IF(C10="","",C10/'Start Here'!$B$10) -> 20000 | E10: 32280 | F10: 16460 | G10: 91060 | I10: =SUM(E10:H10) -> 139800 | J10: =IF(OR(C10="",C10=0),"",I10/C10) -> 1.7475 | K10: =IFERROR(LOOKUP(2,1/(E10:H10<>""),E10:H10),"") -> 91060 | L10: =IF(D10="","Set Goal",IF(K10="","No Data",IF(K10>=D10,"GREEN",IF(K10>=0.85*D10,"YELLOW","RED")))) -> GREEN
A11: Implementations Completed (count) | B11: David Rodriguez (Ops Mgr) | D11: =IF(C11="","",C11/'Start Here'!$B$10) | E11: 13 | F11: 18 | G11: 27 | H11: 26 | I11: =SUM(F11:H11) -> 71 | J11: =IF(OR(C11="",C11=0),"",I11/C11) | K11: =IFERROR(LOOKUP(2,1/(F11:H11<>""),F11:H11),"") -> 26 | L11: =IF(D11="","Set Goal",IF(K11="","No Data",IF(K11>=D11,"GREEN",IF(K11>=0.85*D11,"YELLOW","RED")))) -> Set Goal
A12: Closeouts Submitted (count) | B12: Steve Weaver (PM) | C12: 80000 | D12: =IF(C12="","",C12/'Start Here'!$B$10) -> 20000 | F12: 0 | I12: =SUM(E12:H12) -> 0 | J12: =IF(OR(C12="",C12=0),"",I12/C12) -> 0 | K12: =IFERROR(LOOKUP(2,1/(E12:H12<>""),E12:H12),"") -> 0 | L12: =IF(D12="","Set Goal",IF(K12="","No Data",IF(K12>=D12,"GREEN",IF(K12>=0.85*D12,"YELLOW","RED")))) -> RED
A13: Payments Received ($) | B13: Devon Goforth (Director of Accounting) | C13: 80000 | D13: =IF(C13="","",C13/'Start Here'!$B$10) -> 20000 | E13: 0 | F13: 34320 | I13: =SUM(E13:H13) -> 34320 | J13: =IF(OR(C13="",C13=0),"",I13/C13) -> 0.429 | K13: =IFERROR(LOOKUP(2,1/(E13:H13<>""),E13:H13),"") -> 34320 | L13: =IF(D13="","Set Goal",IF(K13="","No Data",IF(K13>=D13,"GREEN",IF(K13>=0.85*D13,"YELLOW","RED")))) -> GREEN
O14: 87250
A15: BGE Tune-Up | O15: 22319
A16: Program / KPI | B16: Owner | C16: Monthly Goal | D16: Weekly Target | E16: Wk1 9/7 | F16: Wk2 9/14 | G16: Wk3 9/21 | H16: Wk4 9/28 | I16: MTD Actual | J16: % to Monthly Goal | K16: Latest | L16: Status
A17: Audits Completed | B17: David Wilkinson (Lead Engineer) | D17: =IF(C17="","",C17/'Start Here'!$B$10) | E17: 1 | I17: =SUM(E17:H17) -> 1 | J17: =IF(OR(C17="",C17=0),"",I17/C17) | K17: =IFERROR(LOOKUP(2,1/(E17:H17<>""),E17:H17),"") -> 1 | L17: =IF(D17="","Set Goal",IF(K17="","No Data",IF(K17>=D17,"GREEN",IF(K17>=0.85*D17,"YELLOW","RED")))) -> Set Goal
A18: Pre-Approvals Submitted (count) | B18: David Wilkinson (Lead Engineer) | D18: =IF(C18="","",C18/'Start Here'!$B$10) | E18: 11 | I18: =SUM(E18:H18) -> 11 | J18: =IF(OR(C18="",C18=0),"",I18/C18) | K18: =IFERROR(LOOKUP(2,1/(E18:H18<>""),E18:H18),"") -> 11 | L18: =IF(D18="","Set Goal",IF(K18="","No Data",IF(K18>=D18,"GREEN",IF(K18>=0.85*D18,"YELLOW","RED")))) -> Set Goal
A19: Pre-Approvals Submitted ($ Value) | B19: David Wilkinson (Lead Engineer) | C19: 240000 | D19: =IF(C19="","",C19/'Start Here'!$B$10) -> 60000 | E19: 36732 | I19: =SUM(E19:H19) -> 36732 | J19: =IF(OR(C19="",C19=0),"",I19/C19) -> 0.15305 | K19: =IFERROR(LOOKUP(2,1/(E19:H19<>""),E19:H19),"") -> 36732 | L19: =IF(D19="","Set Goal",IF(K19="","No Data",IF(K19>=D19,"GREEN",IF(K19>=0.85*D19,"YELLOW","RED")))) -> RED
A20: Pre-Approvals Approved (count) | B20: David Wilkinson (Lead Engineer) | D20: =IF(C20="","",C20/'Start Here'!$B$10) | E20: 12 | I20: =SUM(E20:H20) -> 12 | J20: =IF(OR(C20="",C20=0),"",I20/C20) | K20: =IFERROR(LOOKUP(2,1/(E20:H20<>""),E20:H20),"") -> 12 | L20: =IF(D20="","Set Goal",IF(K20="","No Data",IF(K20>=D20,"GREEN",IF(K20>=0.85*D20,"YELLOW","RED")))) -> Set Goal
A21: Implementations Scheduled (Est. Incentive $) | B21: David Rodriguez (Ops Mgr) | C21: 240000 | D21: =IF(C21="","",C21/'Start Here'!$B$10) -> 60000 | E21: 87250 | F21: 109569 | I21: =SUM(E21:H21) -> 196819 | J21: =IF(OR(C21="",C21=0),"",I21/C21) -> 0.82007917 | K21: =IFERROR(LOOKUP(2,1/(E21:H21<>""),E21:H21),"") -> 109569 | L21: =IF(D21="","Set Goal",IF(K21="","No Data",IF(K21>=D21,"GREEN",IF(K21>=0.85*D21,"YELLOW","RED")))) -> GREEN
A22: Implementations Completed (count) | B22: David Rodriguez (Ops Mgr) | D22: =IF(C22="","",C22/'Start Here'!$B$10) | E22: 5 | F22: 1 | G22: 2 | H22: 11 | I22: =SUM(E22:H22) -> 19 | J22: =IF(OR(C22="",C22=0),"",I22/C22) | K22: =IFERROR(LOOKUP(2,1/(E22:H22<>""),E22:H22),"") -> 11 | L22: =IF(D22="","Set Goal",IF(K22="","No Data",IF(K22>=D22,"GREEN",IF(K22>=0.85*D22,"YELLOW","RED")))) -> Set Goal
A23: Closeouts Submitted (count) | B23: David Rodriguez (Ops Mgr) | C23: 240000 | D23: =IF(C23="","",C23/'Start Here'!$B$10) -> 60000 | E23: 0 | F23: 0 | I23: =SUM(E23:H23) -> 0 | J23: =IF(OR(C23="",C23=0),"",I23/C23) -> 0 | K23: =IFERROR(LOOKUP(2,1/(E23:H23<>""),E23:H23),"") -> 0 | L23: =IF(D23="","Set Goal",IF(K23="","No Data",IF(K23>=D23,"GREEN",IF(K23>=0.85*D23,"YELLOW","RED")))) -> RED
A24: Payments Received ($) | B24: Devon Goforth (Director of Accounting) | C24: 240000 | D24: =IF(C24="","",C24/'Start Here'!$B$10) -> 60000 | E24: 0 | F24: 21843.5 | I24: =SUM(E24:H24) -> 21843.5 | J24: =IF(OR(C24="",C24=0),"",I24/C24) -> 0.091014583 | K24: =IFERROR(LOOKUP(2,1/(E24:H24<>""),E24:H24),"") -> 21843.5 | L24: =IF(D24="","Set Goal",IF(K24="","No Data",IF(K24>=D24,"GREEN",IF(K24>=0.85*D24,"YELLOW","RED")))) -> RED
A26: BGE Building Performance Tune-Up (BPTU)
A27: Program / KPI | B27: Owner | C27: Monthly Goal | D27: Weekly Target | E27: Wk1 9/7 | F27: Wk2 9/14 | G27: Wk3 9/21 | H27: Wk4 9/28 | I27: MTD Actual | J27: % to Monthly Goal | K27: Latest | L27: Status
A28: # of BPTUs Submitted | B28: David Wilkinson (Lead Engineer) | C28: 10 | D28: =IF(C28="","",C28/'Start Here'!$B$10) -> 2.5 | E28: 0 | I28: =SUM(E28:H28) -> 0 | J28: =IF(OR(C28="",C28=0),"",I28/C28) -> 0 | K28: =IFERROR(LOOKUP(2,1/(E28:H28<>""),E28:H28),"") -> 0 | L28: =IF(D28="","Set Goal",IF(K28="","No Data",IF(K28>=D28,"GREEN",IF(K28>=0.85*D28,"YELLOW","RED")))) -> RED
A29: Total $ of BPTU Phase-1 Applications Submitted | B29: David Wilkinson (Lead Engineer) | C29: 86700 | D29: =IF(C29="","",C29/'Start Here'!$B$10) -> 21675 | E29: 0 | I29: =SUM(E29:H29) -> 0 | J29: =IF(OR(C29="",C29=0),"",I29/C29) -> 0 | K29: =IFERROR(LOOKUP(2,1/(E29:H29<>""),E29:H29),"") -> 0 | L29: =IF(D29="","Set Goal",IF(K29="","No Data",IF(K29>=D29,"GREEN",IF(K29>=0.85*D29,"YELLOW","RED")))) -> RED
A30: $ Value of BPTU Phase-2 Incentive Submitted for Pre-Approval | B30: David Wilkinson (Lead Engineer) | C30: 300000 | D30: =IF(C30="","",C30/'Start Here'!$B$10) -> 75000 | E30: 0 | I30: =SUM(E30:H30) -> 0 | J30: =IF(OR(C30="",C30=0),"",I30/C30) -> 0 | K30: =IFERROR(LOOKUP(2,1/(E30:H30<>""),E30:H30),"") -> 0 | L30: =IF(D30="","Set Goal",IF(K30="","No Data",IF(K30>=D30,"GREEN",IF(K30>=0.85*D30,"YELLOW","RED")))) -> RED
A31: Audits Completed | B31: David Wilkinson (Lead Engineer) | D31: =IF(C31="","",C31/'Start Here'!$B$10) | E31: 1 | I31: =SUM(E31:H31) -> 1 | J31: =IF(OR(C31="",C31=0),"",I31/C31) | K31: =IFERROR(LOOKUP(2,1/(E31:H31<>""),E31:H31),"") -> 1 | L31: =IF(D31="","Set Goal",IF(K31="","No Data",IF(K31>=D31,"GREEN",IF(K31>=0.85*D31,"YELLOW","RED")))) -> Set Goal
A32: Pre-Approvals Submitted (count) | B32: David Wilkinson (Lead Engineer) | D32: =IF(C32="","",C32/'Start Here'!$B$10) | E32: 0 | I32: =SUM(E32:H32) -> 0 | J32: =IF(OR(C32="",C32=0),"",I32/C32) | K32: =IFERROR(LOOKUP(2,1/(E32:H32<>""),E32:H32),"") -> 0 | L32: =IF(D32="","Set Goal",IF(K32="","No Data",IF(K32>=D32,"GREEN",IF(K32>=0.85*D32,"YELLOW","RED")))) -> Set Goal
A33: Pre-Approvals Submitted ($ Value) | B33: David Wilkinson (Lead Engineer) | C33: 386700 | D33: =IF(C33="","",C33/'Start Here'!$B$10) -> 96675 | E33: 0 | I33: =SUM(E33:H33) -> 0 | J33: =IF(OR(C33="",C33=0),"",I33/C33) -> 0 | K33: =IFERROR(LOOKUP(2,1/(E33:H33<>""),E33:H33),"") -> 0 | L33: =IF(D33="","Set Goal",IF(K33="","No Data",IF(K33>=D33,"GREEN",IF(K33>=0.85*D33,"YELLOW","RED")))) -> RED
A34: Pre-Approvals Approved (count) | B34: David Wilkinson (Lead Engineer) | D34: =IF(C34="","",C34/'Start Here'!$B$10) | E34: 2 | I34: =SUM(E34:H34) -> 2 | J34: =IF(OR(C34="",C34=0),"",I34/C34) | K34: =IFERROR(LOOKUP(2,1/(E34:H34<>""),E34:H34),"") -> 2 | L34: =IF(D34="","Set Goal",IF(K34="","No Data",IF(K34>=D34,"GREEN",IF(K34>=0.85*D34,"YELLOW","RED")))) -> Set Goal
A35: Implementations Scheduled (Est. Incentive $) | B35: David Rodriguez (Ops Mgr) | C35: 300000 | D35: =IF(C35="","",C35/'Start Here'!$B$10) -> 75000 | E35: 36852 | F35: 0 | I35: =SUM(E35:H35) -> 36852 | J35: =IF(OR(C35="",C35=0),"",I35/C35) -> 0.12284 | K35: =IFERROR(LOOKUP(2,1/(E35:H35<>""),E35:H35),"") -> 0 | L35: =IF(D35="","Set Goal",IF(K35="","No Data",IF(K35>=D35,"GREEN",IF(K35>=0.85*D35,"YELLOW","RED")))) -> RED
A36: Implementations Completed (count) | B36: David Rodriguez (Ops Mgr) | D36: =IF(C36="","",C36/'Start Here'!$B$10) | E36: 0 | F36: 3 | G36: 0 | H36: 1 | I36: =SUM(E36:H36) -> 4 | J36: =IF(OR(C36="",C36=0),"",I36/C36) | K36: =IFERROR(LOOKUP(2,1/(E36:H36<>""),E36:H36),"") -> 1 | L36: =IF(D36="","Set Goal",IF(K36="","No Data",IF(K36>=D36,"GREEN",IF(K36>=0.85*D36,"YELLOW","RED")))) -> Set Goal
A37: Closeouts Submitted (count) | B37: David Rodriguez (Ops Mgr) | C37: 300000 | D37: =IF(C37="","",C37/'Start Here'!$B$10) -> 75000 | I37: =SUM(E37:H37) -> 0 | J37: =IF(OR(C37="",C37=0),"",I37/C37) -> 0 | K37: =IFERROR(LOOKUP(2,1/(E37:H37<>""),E37:H37),"") | L37: =IF(D37="","Set Goal",IF(K37="","No Data",IF(K37>=D37,"GREEN",IF(K37>=0.85*D37,"YELLOW","RED")))) -> No Data
A38: Payments Received ($) | B38: Devon Goforth (Director of Accounting) | C38: 300000 | D38: =IF(C38="","",C38/'Start Here'!$B$10) -> 75000 | E38: 0 | F38: 161797 | I38: =SUM(E38:H38) -> 161797 | J38: =IF(OR(C38="",C38=0),"",I38/C38) -> 0.53932333 | K38: =IFERROR(LOOKUP(2,1/(E38:H38<>""),E38:H38),"") -> 161797 | L38: =IF(D38="","Set Goal",IF(K38="","No Data",IF(K38>=D38,"GREEN",IF(K38>=0.85*D38,"YELLOW","RED")))) -> GREEN
A40: Pepco / WGL
A41: Program / KPI | B41: Owner | C41: Monthly Goal | D41: Weekly Target | E41: Wk1 9/7 | F41: Wk2 9/14 | G41: Wk3 9/21 | H41: Wk4 9/28 | I41: MTD Actual | J41: % to Monthly Goal | K41: Latest | L41: Status
A42: Audits Completed | B42: Ameya (Lead Engineer) | D42: =IF(C42="","",C42/'Start Here'!$B$10) | E42: 1 | I42: =SUM(E42:H42) -> 1 | J42: =IF(OR(C42="",C42=0),"",I42/C42) | K42: =IFERROR(LOOKUP(2,1/(E42:H42<>""),E42:H42),"") -> 1 | L42: =IF(D42="","Set Goal",IF(K42="","No Data",IF(K42>=D42,"GREEN",IF(K42>=0.85*D42,"YELLOW","RED")))) -> Set Goal
A43: Pre-Approvals Submitted (count) | B43: Ameya (Lead Engineer) | D43: =IF(C43="","",C43/'Start Here'!$B$10) | E43: 1 | I43: =SUM(E43:H43) -> 1 | J43: =IF(OR(C43="",C43=0),"",I43/C43) | K43: =IFERROR(LOOKUP(2,1/(E43:H43<>""),E43:H43),"") -> 1 | L43: =IF(D43="","Set Goal",IF(K43="","No Data",IF(K43>=D43,"GREEN",IF(K43>=0.85*D43,"YELLOW","RED")))) -> Set Goal
...

Sheet Direct Install
A1: Direct Install
A2: Sales through closeout for the Direct Install track
A4: Weekly KPIs
A5: Program / KPI | B5: Owner | C5: Monthly Goal | D5: Weekly Target | E5: Wk1 9/7 | F5: Wk2 9/14 | G5: Wk3 9/21 | H5: Wk4 9/28 | I5: MTD Actual | J5: % to Monthly Goal | K5: Latest | L5: Status
A6: Sales ($) | B6: Adriana | C6: 300000 | D6: =IF(C6="","",C6/'Start Here'!$B$10) -> 75000 | E6: 0 | F6: 0 | I6: =SUM(E6:H6) -> 0 | J6: =IF(OR(C6="",C6=0),"",I6/C6) -> 0 | K6: =IFERROR(LOOKUP(2,1/(E6:H6<>""),E6:H6),"") -> 0 | L6: =IF(D6="","Set Goal",IF(K6="","No Data",IF(K6>=D6,"GREEN",IF(K6>=0.85*D6,"YELLOW","RED")))) -> RED
A7: Approved / Available Projects | B7: Steve Weaver | D7: =IF(C7="","",C7/'Start Here'!$B$10) | E7: 0 | I7: =SUM(E7:H7) -> 0 | J7: =IF(OR(C7="",C7=0),"",I7/C7) | K7: =IFERROR(LOOKUP(2,1/(E7:H7<>""),E7:H7),"") -> 0 | L7: =IF(D7="","Set Goal",IF(K7="","No Data",IF(K7>=D7,"GREEN",IF(K7>=0.85*D7,"YELLOW","RED")))) -> Set Goal
A8: Installs Scheduled | B8: Steve Weaver | D8: =IF(C8="","",C8/'Start Here'!$B$10) | E8: 2 | I8: =SUM(E8:H8) -> 2 | J8: =IF(OR(C8="",C8=0),"",I8/C8) | K8: =IFERROR(LOOKUP(2,1/(E8:H8<>""),E8:H8),"") -> 2 | L8: =IF(D8="","Set Goal",IF(K8="","No Data",IF(K8>=D8,"GREEN",IF(K8>=0.85*D8,"YELLOW","RED")))) -> Set Goal
A9: Installs Completed | B9: Steve Weaver | D9: =IF(C9="","",C9/'Start Here'!$B$10) | E9: 0 | I9: =SUM(E9:H9) -> 0 | J9: =IF(OR(C9="",C9=0),"",I9/C9) | K9: =IFERROR(LOOKUP(2,1/(E9:H9<>""),E9:H9),"") -> 0 | L9: =IF(D9="","Set Goal",IF(K9="","No Data",IF(K9>=D9,"GREEN",IF(K9>=0.85*D9,"YELLOW","RED")))) -> Set Goal
A10: Revenue ($) | B10: Devon Goforth (Director of Accounting) | C10: 300000 | D10: =IF(C10="","",C10/'Start Here'!$B$10) -> 75000 | I10: =SUM(E10:H10) -> 0 | J10: =IF(OR(C10="",C10=0),"",I10/C10) -> 0 | K10: =IFERROR(LOOKUP(2,1/(E10:H10<>""),E10:H10),"") | L10: =IF(D10="","Set Goal",IF(K10="","No Data",IF(K10>=D10,"GREEN",IF(K10>=0.85*D10,"YELLOW","RED")))) -> No Data
A11: Closeouts Submitted | B11: Steve Weaver | C11: 300000 | D11: =IF(C11="","",C11/'Start Here'!$B$10) -> 75000 | E11: 0 | F11: 0 | I11: =SUM(E11:H11) -> 0 | J11: =IF(OR(C11="",C11=0),"",I11/C11) -> 0 | K11: =IFERROR(LOOKUP(2,1/(E11:H11<>""),E11:H11),"") -> 0 | L11: =IF(D11="","Set Goal",IF(K11="","No Data",IF(K11>=D11,"GREEN",IF(K11>=0.85*D11,"YELLOW","RED")))) -> RED
A12: Payments Received ($) | B12: Devon Goforth (Director of Accounting) | C12: 300000 | D12: =IF(C12="","",C12/'Start Here'!$B$10) -> 75000 | E12: 96632.37 | F12: 1442.62 | I12: =SUM(E12:H12) -> 98074.99 | J12: =IF(OR(C12="",C12=0),"",I12/C12) -> 0.32691663 | K12: =IFERROR(LOOKUP(2,1/(E12:H12<>""),E12:H12),"") -> 1442.62 | L12: =IF(D12="","Set Goal",IF(K12="","No Data",IF(K12>=D12,"GREEN",IF(K12>=0.85*D12,"YELLOW","RED")))) -> RED
A14: Gross Margin % — consider tracking monthly only rather than weekly, per your notes

Sheet Recurring Revenue
A1: Recurring Revenue
A2: Zentility, HVAC/BAS service agreements, renewals, and the prescriptive pipeline
A4: Weekly KPIs
A5: Program / KPI | B5: Owner | C5: Monthly Goal | D5: Weekly Target | E5: Wk1 9/7 | F5: Wk2 9/14 | G5: Wk3 9/21 | H5: Wk4 9/28 | I5: MTD Actual | J5: % to Monthly Goal | K5: Latest | L5: Status
A6: New Service Contracts Sold | B6: John R. | C6: 5 | D6: =IF(C6="","",C6/'Start Here'!$B$10) -> 1.25 | I6: =SUM(E6:H6) -> 0 | J6: =IF(OR(C6="",C6=0),"",I6/C6) -> 0 | K6: =IFERROR(LOOKUP(2,1/(E6:H6<>""),E6:H6),"") | L6: =IF(D6="","Set Goal",IF(K6="","No Data",IF(K6>=D6,"GREEN",IF(K6>=0.85*D6,"YELLOW","RED")))) -> No Data
A7: Active Recurring Revenue / MRR ($) | B7: Devon Goforth (Director of Accounting) | D7: =IF(C7="","",C7/'Start Here'!$B$10) | I7: =SUM(E7:H7) -> 0 | J7: =IF(OR(C7="",C7=0),"",I7/C7) | K7: =IFERROR(LOOKUP(2,1/(E7:H7<>""),E7:H7),"") | L7: =IF(D7="","Set Goal",IF(K7="","No Data",IF(K7>=D7,"GREEN",IF(K7>=0.85*D7,"YELLOW","RED")))) -> Set Goal
A8: HVAC Service Contracts (count) | B8: John R. | C8: 2 | D8: =IF(C8="","",C8/'Start Here'!$B$10) -> 0.5 | I8: =SUM(E8:H8) -> 0 | J8: =IF(OR(C8="",C8=0),"",I8/C8) -> 0 | K8: =IFERROR(LOOKUP(2,1/(E8:H8<>""),E8:H8),"") | L8: =IF(D8="","Set Goal",IF(K8="","No Data",IF(K8>=D8,"GREEN",IF(K8>=0.85*D8,"YELLOW","RED")))) -> No Data
A9: BAS Service Contracts (count) | B9: Adriana | C9: 1 | D9: =IF(C9="","",C9/'Start Here'!$B$10) -> 0.25 | E9: 0 | F9: 0 | I9: =SUM(E9:H9) -> 0 | J9: =IF(OR(C9="",C9=0),"",I9/C9) -> 0 | K9: =IFERROR(LOOKUP(2,1/(E9:H9<>""),E9:H9),"") -> 0 | L9: =IF(D9="","Set Goal",IF(K9="","No Data",IF(K9>=D9,"GREEN",IF(K9>=0.85*D9,"YELLOW","RED")))) -> RED
A10: Consulting / Ongoing Services (count) | B10: John R. | C10: 3 | D10: =IF(C10="","",C10/'Start Here'!$B$10) -> 0.75 | I10: =SUM(E10:H10) -> 0 | J10: =IF(OR(C10="",C10=0),"",I10/C10) -> 0 | K10: =IFERROR(LOOKUP(2,1/(E10:H10<>""),E10:H10),"") | L10: =IF(D10="","Set Goal",IF(K10="","No Data",IF(K10>=D10,"GREEN",IF(K10>=0.85*D10,"YELLOW","RED")))) -> No Data
A11: Zentility Rate Checks Presented | B11: John R. | C11: 5 | D11: =IF(C11="","",C11/'Start Here'!$B$10) -> 1.25 | I11: =SUM(E11:H11) -> 0 | J11: =IF(OR(C11="",C11=0),"",I11/C11) -> 0 | K11: =IFERROR(LOOKUP(2,1/(E11:H11<>""),E11:H11),"") | L11: =IF(D11="","Set Goal",IF(K11="","No Data",IF(K11>=D11,"GREEN",IF(K11>=0.85*D11,"YELLOW","RED")))) -> No Data
A12: Zentility Contracts Signed | B12: John R. | C12: 2 | D12: =IF(C12="","",C12/'Start Here'!$B$10) -> 0.5 | I12: =SUM(E12:H12) -> 0 | J12: =IF(OR(C12="",C12=0),"",I12/C12) -> 0 | K12: =IFERROR(LOOKUP(2,1/(E12:H12<>""),E12:H12),"") | L12: =IF(D12="","Set Goal",IF(K12="","No Data",IF(K12>=D12,"GREEN",IF(K12>=0.85*D12,"YELLOW","RED")))) -> No Data
A13: Renewals Due | B13: Adriana | D13: 0 | E13: 0 | F13: 0 | I13: =SUM(E13:H13) -> 0 | J13: =IF(OR(C13="",C13=0),"",I13/C13) | K13: =IFERROR(LOOKUP(2,1/(E13:H13<>""),E13:H13),"") -> 0 | L13: =IF(D13="","Set Goal",IF(K13="","No Data",IF(K13>=D13,"GREEN",IF(K13>=0.85*D13,"YELLOW","RED")))) -> GREEN
A14: Renewals Completed | B14: Adriana | D14: 0 | E14: 0 | F14: 0 | I14: =SUM(E14:H14) -> 0 | J14: =IF(OR(C14="",C14=0),"",I14/C14) | K14: =IFERROR(LOOKUP(2,1/(E14:H14<>""),E14:H14),"") -> 0 | L14: =IF(D14="","Set Goal",IF(K14="","No Data",IF(K14>=D14,"GREEN",IF(K14>=0.85*D14,"YELLOW","RED")))) -> GREEN
A15: Recurring Revenue Billed / Received ($) | B15: Devon Goforth (Director of Accounting) | D15: =IF(C15="","",C15/'Start Here'!$B$10) | I15: =SUM(E15:H15) -> 0 | J15: =IF(OR(C15="",C15=0),"",I15/C15) | K15: =IFERROR(LOOKUP(2,1/(E15:H15<>""),E15:H15),"") | L15: =IF(D15="","Set Goal",IF(K15="","No Data",IF(K15>=D15,"GREEN",IF(K15>=0.85*D15,"YELLOW","RED")))) -> Set Goal
A17: EmPower MD Prescriptive HVAC Tune-Ups now has its own full priority section on the Tune-Up Factory tab (Demand through Cash) — tracked there instead of as a single row here.

Sheet Aging & Stalled Work
A1: Aging & Stalled Work
A2: What is HBS sitting on internally? Target is zero — this is controllable.
A4: Internal Response-Time Aging
A5: Item | B5: Owner | C5: Max Acceptable | D5: Wk1 9/7 | E5: Wk2 9/14 | F5: Wk3 9/21 | G5: Wk4 9/28 | H5: Latest | I5: Status
A6: Pre-Approvals Awaiting HBS Response > 7 Days (All Programs) | B6: Ameya (Lead Engineer) | C6: 0 | H6: =IFERROR(LOOKUP(2,1/(D6:G6<>""),D6:G6),"") | I6: =IF(H6="","No Data",IF(H6<=C6,"GREEN",IF(H6<=C6+2,"YELLOW","RED"))) -> No Data
A7: Closeouts Awaiting HBS Response > 7 Days (All Programs) | B7: Ameya (Lead Engineer) | C7: 0 | H7: =IFERROR(LOOKUP(2,1/(D7:G7<>""),D7:G7),"") | I7: =IF(H7="","No Data",IF(H7<=C7,"GREEN",IF(H7<=C7+2,"YELLOW","RED"))) -> No Data
A9: These count external-facing utility delays as normal; the 7-day threshold is HBS's own response time. Green = 0 outstanding, Yellow = 1-2, Red = 3+.

Sheet Issues & Actions
A1: Issues & Actions
A2: Only Red KPIs land here — why it's red, what we're doing, who owns it, by when
A4: Date | B4: Area / KPI | C4: Why Is It Red? | D4: Corrective Action | E4: Owner | F4: Due Date | G4: Status
A5: 46279 | B5: Prescriptive | C5: Lack of team to complete work | D5: We have 17 ready for close out and need eng to help close out | E5: Steve | F5: 46283
